Exception in thread Thread-4:
Traceback (most recent call last):
  File "/usr/lib/python3.8/threading.py", line 932, in _bootstrap_inner
    self.run()
  File "/usr/lib/python3.8/threading.py", line 870, in run
    self._target(*self._args, **self._kwargs)
  File "/net/femto/C/All Projects/LaserLab/Software/libraries/lcp-video/lcp_video/flir_camera/flir_camera_DL.py", line 872, in recording_run
    self.recording_create_file(filename,Nframes)
  File "/net/femto/C/All Projects/LaserLab/Software/libraries/lcp-video/lcp_video/flir_camera/flir_camera_DL.py", line 813, in recording_create_file
    f.create_dataset('black level all', data = self.black_level['all'])
  File "/net/femto/C/All Projects/LaserLab/Software/libraries/lcp-video/lcp_video/flir_camera/flir_camera_DL.py", line 402, in get_black_level
    digital = self.cam.BlackLevel.GetValue()*4095/100
  File "/home/femtoland/.local/lib/python3.8/site-packages/PySpin.py", line 6775, in GetValue
    return _PySpin.IFloat_GetValue(self, Verify, IgnoreCache)
_PySpin.SpinnakerException: Spinnaker: Error reading from device at register address: 00106844. Please try reconnecting the device. [-1010]

